Workbook

Sheet Sheet1
A1: Request No | B1: RCA No | C1: Date_of_Request | D1: Date_of_Report | E1: Model | F1: Customer | G1: Serial Number | H1: Def_ID | I1: Official_Defect_Name | J1: Defect Category | K1: Defect Name | L1: Severity_Level | M1: Detect_By | N1: Stage | O1: During_Process | P1: How_Much | Q1: Main_Impact | R1: Phenomenon | S1: Verify Phenomenon | T1: Link Photo of Phenomenon | U1: Url Photo | V1: Task Id | W1: Analyze_Process | X1: Part_Replacement | Y1: Materials | Z1: Machine/Jig | AA1: Man | AB1: Methode | AC1: 4M_Potential_Cause | AD1: W0 | AE1: W1 | AF1: W2 | AG1: W3 | AH1: W4 | AI1: 5-Why_Analyze | AJ1: Root Cause | AK1: Corrective_Action | AL1: Preventive_Action | AM1: Action Item | AN1: Created By
A2: AR241125015913 | C2: 45621 | E2: Takatsu-8 Autocutter | H2: =VLOOKUP(Table1[[#This Row],[Official_Defect_Name]],Sheet2!$A:$F,2,FALSE) -> TKSAL-004 | I2: Abnormal PGU Movement | K2: Abnormal PGU Movement | L2: =VLOOKUP(Table1[[#This Row],[Official_Defect_Name]],Table3[#All],6,1) -> #N/A | M2: Operator | N2: STAGE PH 2 | R2: PGU seret saat open/close .
A3: AR241128030530 | C3: 45624 | E3: Takatsu-4 Autocutter | H3: =VLOOKUP(Table1[[#This Row],[Official_Defect_Name]],Sheet2!$A:$F,2,FALSE) -> TKSAL-010 | I3: DO | K3: DO | L3: =VLOOKUP(Table1[[#This Row],[Official_Defect_Name]],Table3[#All],6,1) -> Critical | M3: Operator | N3: PRINTING | R3: Jig 6
A4: AR241128030601 | C4: 45624 | E4: Takatsu-4 Autocutter | H4: =VLOOKUP(Table1[[#This Row],[Official_Defect_Name]],Sheet2!$A:$F,2,FALSE) -> TKSAL-010 | I4: DO | K4: DO | L4: =VLOOKUP(Table1[[#This Row],[Official_Defect_Name]],Table3[#All],6,1) -> Critical | M4: Operator | N4: PRINTING | R4: Jig 2
A5: AR241128081950 | C5: 45624 | E5: Takatsu-8 Autocutter | H5: =VLOOKUP(Table1[[#This Row],[Official_Defect_Name]],Sheet2!$A:$F,2,FALSE) -> TKSAL-008 | I5: DMAH | K5: DMAH | L5: =VLOOKUP(Table1[[#This Row],[Official_Defect_Name]],Table3[#All],6,1) -> Severity | M5: Operator | N5: PRINTING | R5: Jig 07
A6: AR241202103435 | C6: 45628 | E6: Takatsu-4 Autocutter | H6: =VLOOKUP(Table1[[#This Row],[Official_Defect_Name]],Sheet2!$A:$F,2,FALSE) -> TKSFE-003 | I6: Fatal Error 6727 | K6: Fatal Error 6727 | L6: =VLOOKUP(Table1[[#This Row],[Official_Defect_Name]],Table3[#All],6,1) -> Low | M6: Operator | N6: STG PRINTING | R6: Setelah power on di stg printing | S6: Fatal error 006727 | T6: [{"name":"6727_Nazar Bagus H..jpg","link":"https://epsongroup-my.sharepoint.com/personal/brian_ramdhani_epson_co_id/Documents/Apps/Microsoft%20Forms/TAKATSU%20ANALYZE%20REPORT/Question/6727_Nazar%20Bagus%20H..jpg","id":"01D6UVHSNVD5QK3KJ5KFBYH3PWNW7ZBPXN","type":null,"size":112887,"referenceId":"01D6UVHSOX5DG5RX522VGYFCV365U3UBU3","driveId":"b!7qg8FsnQY0iiT36_x6Novv_3J9v4MtxPsytkCbb-ZPz3ScQFcxKeSqI2jw7AAtnZ","status":1,"uploadSessionUrl":null}] | U6: https://epsongroup-my.sharepoint.com/personal/brian_ramdhani_epson_co_id/Documents/Apps/Microsoft%20Forms/TAKATSU%20ANALYZE%20REPORT/Question/6727_Nazar%20Bagus%20H..jpg | AM6: Change CH77 Main
A7: AR241203025422 | C7: 45629 | E7: Takatsu-4 Autocutter | H7: =VLOOKUP(Table1[[#This Row],[Official_Defect_Name]],Sheet2!$A:$F,2,FALSE) -> TKSAL-017 | I7: Paper Jam | K7: Paper Jam | L7: =VLOOKUP(Table1[[#This Row],[Official_Defect_Name]],Table3[#All],6,1) -> Low | M7: Operator | N7: STG PRINTING | R7: Saat setting paper | S7: During printing menu nozzle check at printing stage, found paper jam | T7: [{"name":"Picture2_Zainul Muttaqin.png","link":"https://epsongroup-my.sharepoint.com/personal/brian_ramdhani_epson_co_id/Documents/Apps/Microsoft%20Forms/TAKATSU%20ANALYZE%20REPORT/Question/Picture2_Zainul%20Muttaqin.png","id":"01D6UVHSM3PCHREI7VGZBISCMYTDIFXVQJ","type":null,"size":909786,"referenceId":"01D6UVHSOX5DG5RX522VGYFCV365U3UBU3","driveId":"b!7qg8FsnQY0iiT36_x6Novv_3J9v4MtxPsytkCbb-ZPz3ScQFcxKeSqI2jw7AAtnZ","status":1,"uploadSessionUrl":null}] | U7: https://epsongroup-my.sharepoint.com/personal/brian_ramdhani_epson_co_id/Documents/Apps/Microsoft%20Forms/TAKATSU%20ANALYZE%20REPORT/Question/Picture2_Zainul%20Muttaqin.png | V7: u6lneZPVp0uCYlaPVWhPOMgACrgC | AJ7: Harness connection Paper Jam Detect was broken, release soldering | AM7: Reminding OPR to carefully during arrange harness connection Paper Jam Detect, and follow SWP | AN7: Zainul Muttaqin
A8: AR241203090108 | C8: 45629 | E8: Takatsu-4 Autocutter | H8: =VLOOKUP(Table1[[#This Row],[Official_Defect_Name]],Sheet2!$A:$F,2,FALSE) -> TKSAL-020 | I8: PF Measurement NG | K8: PF Measurement NG | L8: =VLOOKUP(Table1[[#This Row],[Official_Defect_Name]],Table3[#All],6,1) -> Low | M8: Operator | N8: STG PG | R8: Saat proses pf measurment | S8: During PF Measurement, found Result NG (PF MEASURMENT NG (maincalculation error Aveti_L over)) | T8: [{"name":"PF OK_Nazar Bagus H..jpg","link":"https://epsongroup-my.sharepoint.com/personal/brian_ramdhani_epson_co_id/Documents/Apps/Microsoft%20Forms/TAKATSU%20ANALYZE%20REPORT/Question/PF%20OK_Nazar%20Bagus%20H..jpg","id":"01D6UVHSKD2J6IUD5FNFBZ7T7TWAUQ4ANP","type":null,"size":77030,"referenceId":"01D6UVHSOX5DG5RX522VGYFCV365U3UBU3","driveId":"b!7qg8FsnQY0iiT36_x6Novv_3J9v4MtxPsytkCbb-ZPz3ScQFcxKeSqI2jw7AAtnZ","status":1,"uploadSessionUrl":null}] | U8: https://epsongroup-my.sharepoint.com/personal/brian_ramdhani_epson_co_id/Documents/Apps/Microsoft%20Forms/TAKATSU%20ANALYZE%20REPORT/Question/PF%20OK_Nazar%20Bagus%20H..jpg | V8: edT7obW9EEalpfTUGsfyw8gAGX1k | AM8: Re Check in Line 5x OK (Pn/n : 0/5) --> 4M New Man Power MA04 --> Re Educate Man Power to Ensure Belt Tension meet Specification --> Continue Monitoring | AN8: Nazar Bagus H.
A9: AR241204120145 | C9: 45630 | E9: Takatsu-4 Autocutter | H9: =VLOOKUP(Table1[[#This Row],[Official_Defect_Name]],Sheet2!$A:$F,2,FALSE) -> TKSAL-015 | I9: MNU Measurement NG | K9: MNU Measurement NG | L9: =VLOOKUP(Table1[[#This Row],[Official_Defect_Name]],Table3[#All],6,1) -> Low | M9: Operator | N9: PG | R9: E (Saat proses MNU MEASURMENT) | S9: When MNU Measurement Check, hear Noise different with other product | T9: [{"name":"Screenshot_20241206_134121_Sound Meter_Rio Rizki Khanigia.jpg","link":"https://epsongroup-my.sharepoint.com/personal/brian_ramdhani_epson_co_id/Documents/Apps/Microsoft%20Forms/TAKATSU%20ANALYZE%20REPORT/Question/Screenshot_20241206_134121_Sound%20Meter_Rio%20Rizki%20Khanigia.jpg","id":"01D6UVHSK2UZPBHIQLP5GI5MPXIZQOFUIZ","type":null,"size":150672,"referenceId":"01D6UVHSOX5DG5RX522VGYFCV365U3UBU3","driveId":"b!7qg8FsnQY0iiT36_x6Novv_3J9v4MtxPsytkCbb-ZPz3ScQFcxKeSqI2jw7AAtnZ","status":1,"uploadSessionUrl":null}] | U9: https://epsongroup-my.sharepoint.com/personal/brian_ramdhani_epson_co_id/Documents/Apps/Microsoft%20Forms/TAKATSU%20ANALYZE%20REPORT/Question/Screenshot_20241206_134121_Sound%20Meter_Rio%20Rizki%20Khanigia.jpg | V9: kipjsswdQUKJRBkJRQ3JW8gAFdkV | AJ9: Operator Over judgement during MNU Measurement. We already check with db Meter (Nilai Kebisingan), result measurement OK and NG same value (81-86 db), and not any STD noise db for MNU measurement | AM9: Continue production refer to db meter check OK and NG product same (81-86 db) | AN9: Rio Rizki Khanigia
A10: AR241205084758 | C10: 45631 | E10: Takatsu-8 Autocutter | H10: =VLOOKUP(Table1[[#This Row],[Official_Defect_Name]],Sheet2!$A:$F,2,FALSE) -> TKSAL-004 | I10: Abnormal PGU Movement | K10: Abnormal PGU Movement | L10: =VLOOKUP(Table1[[#This Row],[Official_Defect_Name]],Table3[#All],6,1) -> #N/A | M10: Operator | N10: STAGE PH 2 | R10: Still analize | S10: PGU Seret saat fitting check di mechanism | T10: [{"name":"PGU Seret_Nazar Bagus H..jpg","link":"https://epsongroup-my.sharepoint.com/personal/brian_ramdhani_epson_co_id/Documents/Apps/Microsoft%20Forms/TAKATSU%20ANALYZE%20REPORT/Question/PGU%20Seret_Nazar%20Bagus%20H..jpg","id":"01D6UVHSKA7KYKTWPB3ZDZMTLK3UF2K4KV","type":null,"size":52789,"referenceId":"01D6UVHSOX5DG5RX522VGYFCV365U3UBU3","driveId":"b!7qg8FsnQY0iiT36_x6Novv_3J9v4MtxPsytkCbb-ZPz3ScQFcxKeSqI2jw7AAtnZ","status":1,"uploadSessionUrl":null}] | U10: https://epsongroup-my.sharepoint.com/personal/brian_ramdhani_epson_co_id/Documents/Apps/Microsoft%20Forms/TAKATSU%20ANALYZE%20REPORT/Question/PGU%20Seret_Nazar%20Bagus%20H..jpg | V10: FWaQ3dCi2kqfGVE22BJpdMgAHYsZ | AJ10: Frame PF Right slighty not fix | AM10: Additional Hold Frame PF Right During Screwing --> Check Any Related Part CHaracter on This Phenomenon | AN10: Nazar Bagus H.
A11: AR241205092813 | C11: 45631 | E11: Takatsu-8 Autocutter | H11: =VLOOKUP(Table1[[#This Row],[Official_Defect_Name]],Sheet2!$A:$F,2,FALSE) -> TKSAL-004 | I11: Abnormal PGU Movement | K11: Abnormal PGU Movement | L11: =VLOOKUP(Table1[[#This Row],[Official_Defect_Name]],Table3[#All],6,1) -> #N/A | M11: Operator | N11: STG PH 2 | R11: Stil analize | V11: q0NSErwdaEOccNo9iIQJt8gALOg6
A12: AR241205121653 | E12: Takatsu-8 Autocutter | H12: =VLOOKUP(Table1[[#This Row],[Official_Defect_Name]],Sheet2!$A:$F,2,FALSE) -> TKSAL-009 | I12: DMAV | K12: DMAV | L12: =VLOOKUP(Table1[[#This Row],[Official_Defect_Name]],Table3[#All],6,1) -> Severity | M12: Operator | N12: PRINTING | R12: Jig 6 | S12: Found DMAV on Printing Result | T12: [{"name":"DMAV_Nazar Bagus H..jpg","link":"https://epsongroup-my.sharepoint.com/personal/brian_ramdhani_epson_co_id/Documents/Apps/Microsoft%20Forms/TAKATSU%20ANALYZE%20REPORT/Question/DMAV_Nazar%20Bagus%20H..jpg","id":"01D6UVHSMNWKBPD4EQCJD3NIMHNLGZORHR","type":null,"size":52376,"referenceId":"01D6UVHSOX5DG5RX522VGYFCV365U3UBU3","driveId":"b!7qg8FsnQY0iiT36_x6Novv_3J9v4MtxPsytkCbb-ZPz3ScQFcxKeSqI2jw7AAtnZ","status":1,"uploadSessionUrl":null}] | U12: https://epsongroup-my.sharepoint.com/personal/brian_ramdhani_epson_co_id/Documents/Apps/Microsoft%20Forms/TAKATSU%20ANALYZE%20REPORT/Question/DMAV_Nazar%20Bagus%20H..jpg | V12: M2f-exdvGEu6yjDF0yIG4sgANkF4 | AJ12: Print Head Dirty | AM12: Wiping Print Head di Repair OK | AN12: Nazar Bagus H.
A13: AR241209101122 | C13: 45635 | E13: Takatsu-8 Autocutter | H13: =VLOOKUP(Table1[[#This Row],[Official_Defect_Name]],Sheet2!$A:$F,2,FALSE) -> TKSAL-004 | I13: Abnormal PGU Movement | K13: Abnormal PGU Movement | L13: =VLOOKUP(Table1[[#This Row],[Official_Defect_Name]],Table3[#All],6,1) -> #N/A | M13: Operator | N13: EXTERNAL | R13: PGU seret saat buka - tutup | S13: At External when Operator check PGU Movement, find little hard to Open | T13: [{"name":"20241209_115941 Copy_Rio Rizki Khanigia 1.jpg","link":"https://epsongroup-my.sharepoint.com/personal/brian_ramdhani_epson_co_id/Documents/Apps/Microsoft%20Forms/TAKATSU%20ANALYZE%20REPORT/Question/20241209_115941%20Copy_Rio%20Rizki%20Khanigia%201.jpg","id":"01D6UVHSKJ5OIIHMCOQNBLHCUW3GAFRV5Y","type":null,"size":2116186,"referenceId":"01D6UVHSOX5DG5RX522VGYFCV365U3UBU3","driveId":"b!7qg8FsnQY0iiT36_x6Novv_3J9v4MtxPsytkCbb-ZPz3ScQFcxKeSqI2jw7AAtnZ","status":1,"uploadSessionUrl":null}] | V13: YU41i0Rov0a-gBOezRRzGMgAL_3y | AJ13: Fixture Case Lower not Flat cause not yet POM Supporting | AM13: Additional POM Holder at Case Lower Assembly Fixture 2 Pcs, and monitoring impact improvement with marking "D" at wagon identity product | AN13: Rio Rizki Khanigia
A14: AR241210025830 | C14: 45636 | E14: Takatsu-8 Autocutter | H14: =VLOOKUP(Table1[[#This Row],[Official_Defect_Name]],Sheet2!$A:$F,2,FALSE) -> TKSAL-025 | I14: Shutter Check Noise | K14: Shutter Check Noise | L14: =VLOOKUP(Table1[[#This Row],[Official_Defect_Name]],Table3[#All],6,1) -> Low | M14: Operator | N14: STG PG | R14: Saat proses shutter chek | V14: hwwsGexcqkyBCQ4x7IWK0cgAOnhK
A15: AR241210052057 | C15: 45636 | E15: Takatsu-8 Autocutter | H15: =VLOOKUP(Table1[[#This Row],[Official_Defect_Name]],Sheet2!$A:$F,2,FALSE) -> TKSAL-025 | I15: Shutter Check Noise | K15: Shutter Check Noise | L15: =VLOOKUP(Table1[[#This Row],[Official_Defect_Name]],Table3[#All],6,1) -> Low | M15: Operator | N15: STG PG | R15: Saat proses pg | S15: During shutter check at PG Stage, found noise platen near on spur gear platen area (Pn/n: 2/35) | T15: [{"name":"Shutter Noise caused by Spur Gear_Zainul Muttaqin.jpg","link":"https://epsongroup-my.sharepoint.com/personal/brian_ramdhani_epson_co_id/Documents/Apps/Microsoft%20Forms/TAKATSU%20ANALYZE%20REPORT/Question/Shutter%20Noise%20caused%20by%20Spur%20Gear_Zainul%20Muttaqin.jpg","id":"01D6UVHSN7ZTIGG5N3TJAZACF7WX63WPA3","type":null,"size":67004,"referenceId":"01D6UVHSOX5DG5RX522VGYFCV365U3UBU3","driveId":"b!7qg8FsnQY0iiT36_x6Novv_3J9v4MtxPsytkCbb-ZPz3ScQFcxKeSqI2jw7AAtnZ","status":1,"uploadSessionUrl":null}] | U15: https://epsongroup-my.sharepoint.com/personal/brian_ramdhani_epson_co_id/Documents/Apps/Microsoft%20Forms/TAKATSU%20ANALYZE%20REPORT/Question/Shutter%20Noise%20caused%20by%20Spur%20Gear_Zainul%20Muttaqin.jpg | V15: FocLiBfpgU--IwLEtS7bMMgAFNau | AJ15: Suspect mistake placement by OPR on WIP, but we still continue monitoring and still analyze to find rootcause. | AM15: Correction placement motor platen by OPR and continue monitoring this defect. | AN15: Zainul Muttaqin
A16: AR241210073009 | C16: 45636 | E16: Takatsu-8 Autocutter | H16: =VLOOKUP(Table1[[#This Row],[Official_Defect_Name]],Sheet2!$A:$F,2,FALSE) -> TKSAL-004 | I16: Abnormal PGU Movement | K16: Abnormal PGU Movement | L16: =VLOOKUP(Table1[[#This Row],[Official_Defect_Name]],Table3[#All],6,1) -> #N/A | M16: Operator | N16: PRINT HEAD 2 | R16: Still analize | V16: V_oOPkdX4EW6rCGX9hCObsgAAgfu
A17: AR241210093321 | C17: 45636 | E17: Takatsu-8 Autocutter | H17: =VLOOKUP(Table1[[#This Row],[Official_Defect_Name]],Sheet2!$A:$F,2,FALSE) -> TKSAL-003 | I17: Abnormal Paper Loading | K17: Abnormal Paper Loading | L17: =VLOOKUP(Table1[[#This Row],[Official_Defect_Name]],Table3[#All],6,1) -> #N/A | M17: Operator | N17: PG | R17: Saat proses label inspection sheet | S17: During label calibration at PG Stage, panel shown [the paper not loaded correctly] | T17: [{"name":"the paper is not loaded correctly_Zainul Muttaqin 1.jpg","link":"https://epsongroup-my.sharepoint.com/personal/brian_ramdhani_epson_co_id/Documents/Apps/Microsoft%20Forms/TAKATSU%20ANALYZE%20REPORT/Question/the%20paper%20is%20not%20loaded%20correctly_Zainul%20Muttaqin%201.jpg","id":"01D6UVHSJCMEDKSOFB5BG2DRUPR5MIYFI6","type":null,"size":34192,"referenceId":"01D6UVHSOX5DG5RX522VGYFCV365U3UBU3","driveId":"b!7qg8FsnQY0iiT36_x6Novv_3J9v4MtxPsytkCbb-ZPz3ScQFcxKeSqI2jw7AAtnZ","status":1,"uploadSessionUrl":null}] | U17: https://epsongroup-my.sharepoint.com/personal/brian_ramdhani_epson_co_id/Documents/Apps/Microsoft%20Forms/TAKATSU%20ANALYZE%20REPORT/Question/the%20paper%20is%20not%20loaded%20correctly_Zainul%20Muttaqin%201.jpg | V17: RKyWbVPnkkynq89fpEd3vMgAKG7u | AJ17: BM Sensor NG - Still Analyze | AM17: Change BM Sensor NG - Continue monitoring this defect | AN17: Zainul Muttaqin
A18: AR241211010730 | C18: 45637 | E18: Takatsu-8 Autocutter | H18: =VLOOKUP(Table1[[#This Row],[Official_Defect_Name]],Sheet2!$A:$F,2,FALSE) -> TKSFE-002 | I18: Fatal Error 5151 | K18: Fatal Error 5151 | L18: =VLOOKUP(Table1[[#This Row],[Official_Defect_Name]],Table3[#All],6,1) -> High | M18: Operator | N18: STG PRINTING | R18: Saat proses power on | S18: During initialize product on Printing Stage, found fatal error 005151 | T18: [{"name":"FE 05151_Zainul Muttaqin.jpg","link":"https://epsongroup-my.sharepoint.com/personal/brian_ramdhani_epson_co_id/Documents/Apps/Microsoft%20Forms/TAKATSU%20ANALYZE%20REPORT/Question/FE%2005151_Zainul%20Muttaqin.jpg","id":"01D6UVHSLNEATZB7FRQFDZFZSNFBZSMHXE","type":null,"size":87766,"referenceId":"01D6UVHSOX5DG5RX522VGYFCV365U3UBU3","driveId":"b!7qg8FsnQY0iiT36_x6Novv_3J9v4MtxPsytkCbb-ZPz3ScQFcxKeSqI2jw7AAtnZ","status":1,"uploadSessionUrl":null}] | U18: https://epsongroup-my.sharepoint.com/personal/brian_ramdhani_epson_co_id/Documents/Apps/Microsoft%20Forms/TAKATSU%20ANALYZE%20REPORT/Question/FE%2005151_Zainul%20Muttaqin.jpg | V18: id7V16wGGkKRwoZTweG2QMgAPm_D | AJ18: OPR forget take out Jig head incline adjustment | AM18: Reminding OPR to must be take out all of Jig, if adjustment process already finished | AN18: Zainul Muttaqin
A19: AR241212080711 | C19: 45638 | E19: Takatsu-4 Autocutter | H19: =VLOOKUP(Table1[[#This Row],[Official_Defect_Name]],Sheet2!$A:$F,2,FALSE) -> TKSAL-005 | I19: Abnormal Power On | K19: Abnormal Power On | L19: =VLOOKUP(Table1[[#This Row],[Official_Defect_Name]],Table3[#All],6,1) -> #N/A | M19: Operator | N19: STG INTETNAL | R19: Standar lcd tampilannya warna hitam actual warna putih | S19: During initial power ON product at Internal Stage, found abnormal LCD Panel [Blue Color] | T19: [{"name":"Abnormal LCD Panel_Zainul Muttaqin.jpg","link":"https://epsongroup-my.sharepoint.com/personal/brian_ramdhani_epson_co_id/Documents/Apps/Microsoft%20Forms/TAKATSU%20ANALYZE%20REPORT/Question/Abnormal%20LCD%20Panel_Zainul%20Muttaqin.jpg","id":"01D6UVHSNJLL5DGMJ2YJFJBRKPCZDABKRS","type":null,"size":60358,"referenceId":"01D6UVHSOX5DG5RX522VGYFCV365U3UBU3","driveId":"b!7qg8FsnQY0iiT36_x6Novv_3J9v4MtxPsytkCbb-ZPz3ScQFcxKeSqI2jw7AAtnZ","status":1,"uploadSessionUrl":null}] | U19: https://epsongroup-my.sharepoint.com/personal/brian_ramdhani_epson_co_id/Documents/Apps/Microsoft%20Forms/TAKATSU%20ANALYZE%20REPORT/Question/Abnormal%20LCD%20Panel_Zainul%20Muttaqin.jpg | V19: TohOXcnnhk6KybuE1l-0YsgAJOu6 | AJ19: FFC connection to board peeled off | AM19: Change FFC peeled of by OPR on SA - Reminding OPR SA, must be follow checkpoint on SWP | AN19: Zainul Muttaqin
A20: AR241212080917 | C20: 45638 | E20: Takatsu-4 Autocutter | H20: =VLOOKUP(Table1[[#This Row],[Official_Defect_Name]],Sheet2!$A:$F,2,FALSE) -> TKSAL-007 | I20: CSIC Check NG | K20: CSIC Check NG | L20: =VLOOKUP(Table1[[#This Row],[Official_Defect_Name]],Table3[#All],6,1) -> #N/A | M20: Operator | N20: STG INTERNAL | R20: Saat proses power on | V20: yseZav0jekaV_wR25gN_1sgADKaH
A21: AR241216032702 | C21: 45642 | E21: Takatsu-4 Autocutter | H21: =VLOOKUP(Table1[[#This Row],[Official_Defect_Name]],Sheet2!$A:$F,2,FALSE) -> TKSAL-010 | I21: DO | K21: DO | L21: =VLOOKUP(Table1[[#This Row],[Official_Defect_Name]],Table3[#All],6,1) -> Critical | M21: Operator | N21: PRINTING | R21: Jig 01 | S21: During Initial Charge Found Dot Omission | T21: [{"name":"DO 17 Dec 24_Nazar Bagus H..png","link":"https://epsongroup-my.sharepoint.com/personal/brian_ramdhani_epson_co_id/Documents/Apps/Microsoft%20Forms/TAKATSU%20ANALYZE%20REPORT/Question/DO%2017%20Dec%2024_Nazar%20Bagus%20H..png","id":"01D6UVHSLLXBNGQZS3D5A3LFMANB5VZNJ3","type":null,"size":2957802,"referenceId":"01D6UVHSOX5DG5RX522VGYFCV365U3UBU3","driveId":"b!7qg8FsnQY0iiT36_x6Novv_3J9v4MtxPsytkCbb-ZPz3ScQFcxKeSqI2jw7AAtnZ","status":1,"uploadSessionUrl":null}] | U21: https://epsongroup-my.sharepoint.com/personal/brian_ramdhani_epson_co_id/Documents/Apps/Microsoft%20Forms/TAKATSU%20ANALYZE%20REPORT/Question/DO%2017%20Dec%2024_Nazar%20Bagus%20H..png | V21: Ln3jCsAQo0OUyMukF-cvJ8gAHcH4 | AJ21: Possibility Electrical Inside PH NG | AM21: Change Print Head in Line (Keep PH for analyze) | AN21: Nazar Bagus H.
A22: AR241216041826 | C22: 45642 | E22: Takatsu-8 Autocutter | H22: =VLOOKUP(Table1[[#This Row],[Official_Defect_Name]],Sheet2!$A:$F,2,FALSE) -> TKSAL-027 | I22: Unstable Printing | K22: Unstable Printing | L22: =VLOOKUP(Table1[[#This Row],[Official_Defect_Name]],Table3[#All],6,1) -> Low | M22: Operator | N22: PRINTING | R22: Jig 06 | S22: During Initial Charge Found Unstable Printing | T22: [{"name":"DMAV_Nazar Bagus H. 1.jpg","link":"https://epsongroup-my.sharepoint.com/personal/brian_ramdhani_epson_co_id/Documents/Apps/Microsoft%20Forms/TAKATSU%20ANALYZE%20REPORT/Question/DMAV_Nazar%20Bagus%20H.%201.jpg","id":"01D6UVHSKQVI3KDSWYCBELLYMQT2IW5GMO","type":null,"size":52376,"referenceId":"01D6UVHSOX5DG5RX522VGYFCV365U3UBU3","driveId":"b!7qg8FsnQY0iiT36_x6Novv_3J9v4MtxPsytkCbb-ZPz3ScQFcxKeSqI2jw7AAtnZ","status":1,"uploadSessionUrl":null}] | U22: https://epsongroup-my.sharepoint.com/personal/brian_ramdhani_epson_co_id/Documents/Apps/Microsoft%20Forms/TAKATSU%20ANALYZE%20REPORT/Question/DMAV_Nazar%20Bagus%20H.%201.jpg | V22: fkOre-DHP0yElkythoegLcgAEB6t | AJ22: Possibility any F/M on Print Head | AM22: Wiping PH in Line OK | AN22: Nazar Bagus H.
A23: AR241216054107 | C23: 45642 | E23: Takatsu-8 Autocutter | H23: =VLOOKUP(Table1[[#This Row],[Official_Defect_Name]],Sheet2!$A:$F,2,FALSE) -> TKSAL-001 | I23: Abnormal CR Movement | K23: Abnormal CR Movement | L23: =VLOOKUP(Table1[[#This Row],[Official_Defect_Name]],Table3[#All],6,1) -> #N/A | M23: Operator | N23: STG PG | R23: Saat power on | S23: When power On at PG stage, find Carriage Movement abnormal. Move Home to Away faster | T23: [{"name":"20241216_175552_Rio Rizki Khanigia.jpg","link":"https://epsongroup-my.sharepoint.com/personal/brian_ramdhani_epson_co_id/Documents/Apps/Microsoft%20Forms/TAKATSU%20ANALYZE%20REPORT/Question/20241216_175552_Rio%20Rizki%20Khanigia.jpg","id":"01D6UVHSJ5WIBBWSSXGZFLJD2G7LDITH4Y","type":null,"size":3547694,"referenceId":"01D6UVHSOX5DG5RX522VGYFCV365U3UBU3","driveId":"b!7qg8FsnQY0iiT36_x6Novv_3J9v4MtxPsytkCbb-ZPz3ScQFcxKeSqI2jw7AAtnZ","status":1,"uploadSessionUrl":null}] | U23: https://epsongroup-my.sharepoint.com/personal/brian_ramdhani_epson_co_id/Documents/Apps/Microsoft%20Forms/TAKATSU%20ANALYZE%20REPORT/Question/20241216_175552_Rio%20Rizki%20Khanigia.jpg | V23: tv8jNjaEf0y9Eq5u6TVKqsgAE3SM | AJ23: Possibility when Serial number not create to ROM during initial setting at Internal stage | AM23: Re-initial setting at PG Stage. after OK, back to Internal stage to re-inspection process. | AN23: Rio Rizki Khanigia
A24: AR241216073519 | C24: 45642 | E24: Takatsu-8 Autocutter | H24: =VLOOKUP(Table1[[#This Row],[Official_Defect_Name]],Sheet2!$A:$F,2,FALSE) -> TKSAL-012 | I24: Ink Drop | K24: Ink Drop | L24: =VLOOKUP(Table1[[#This Row],[Official_Defect_Name]],Table3[#All],6,1) -> Low | M24: Operator | N24: SRG PRINTING | R24: Saat proses miss piping (ada suara noise) | S24: Ink Drop during Miss Piping Check at Stage Printing | T24: [{"name":"Tube Pinch_Nazar Bagus H..jpg","link":"https://epsongroup-my.sharepoint.com/personal/brian_ramdhani_epson_co_id/Documents/Apps/Microsoft%20Forms/TAKATSU%20ANALYZE%20REPORT/Question/Tube%20Pinch_Nazar%20Bagus%20H..jpg","id":"01D6UVHSOBEODUYACEZJH2TJ6F4EKAWWKS","type":null,"size":70867,"referenceId":"01D6UVHSOX5DG5RX522VGYFCV365U3UBU3","driveId":"b!7qg8FsnQY0iiT36_x6Novv_3J9v4MtxPsytkCbb-ZPz3ScQFcxKeSqI2jw7AAtnZ","status":1,"uploadSessionUrl":null}] | U24: https://epsongroup-my.sharepoint.com/personal/brian_ramdhani_epson_co_id/Documents/Apps/Microsoft%20Forms/TAKATSU%20ANALYZE%20REPORT/Question/Tube%20Pinch_Nazar%20Bagus%20H..jpg | V24: Y30NrvnvqU-eyM5JGwjWNMgALEpu | AJ24: Tube JIG Maintenance Box Pinched | AM24: Total Disassembly and Total Cleaning by Production --> Remind Operator to always check JIG and tube condition before insert into Product. | AN24: Nazar Bagus H.
A25: AR241217102245 | C25: 45643 | E25: Takatsu-8 Autocutter | H25: =VLOOKUP(Table1[[#This Row],[Official_Defect_Name]],Sheet2!$A:$F,2,FALSE) -> TKSAL-025 | I25: Shutter Check Noise | K25: Shutter Check Noise | L25: =VLOOKUP(Table1[[#This Row],[Official_Defect_Name]],Table3[#All],6,1) -> Low | M25: Operator | N25: PG | R25: Saat proses shutter check | S25: During Shutter Check Heard tik tik Noise | T25: [{"name":"noise shutter check, less grease_Nazar Bagus H..png","link":"https://epsongroup-my.sharepoint.com/personal/brian_ramdhani_epson_co_id/Documents/Apps/Microsoft%20Forms/TAKATSU%20ANALYZE%20REPORT/Question/noise%20shutter%20check,%20less%20grease_Nazar%20Bagus%20H..png","id":"01D6UVHSIGQ4CP27U5BJCZK6KRCGDSTXHB","type":null,"size":2685785,"referenceId":"01D6UVHSOX5DG5RX522VGYFCV365U3UBU3","driveId":"b!7qg8FsnQY0iiT36_x6Novv_3J9v4MtxPsytkCbb-ZPz3ScQFcxKeSqI2jw7AAtnZ","status":1,"uploadSessionUrl":null}] | U25: https://epsongroup-my.sharepoint.com/personal/brian_ramdhani_epson_co_id/Documents/Apps/Microsoft%20Forms/TAKATSU%20ANALYZE%20REPORT/Question/noise%20shutter%20check,%20less%20grease_Nazar%20Bagus%20H..png | V25: XFFiHC-vm0mOF7UZ3xM6eMgAMrxx | AJ25: Less grease on shaft | AM25: Add grease on shaft and noise dissappear | AN25: Nazar Bagus H.
A26: AR241217114509 | C26: 45643 | E26: Takatsu-8 Autocutter | H26: =VLOOKUP(Table1[[#This Row],[Official_Defect_Name]],Sheet2!$A:$F,2,FALSE) -> TKSAL-004 | I26: Abnormal PGU Movement | K26: Abnormal PGU Movement | L26: =VLOOKUP(Table1[[#This Row],[Official_Defect_Name]],Table3[#All],6,1) -> #N/A | M26: Operator | N26: STG PH | R26: Seret saat buka tutup pgu | S26: During open-close PGU on PH stage, found hard to open-close | T26: [{"name":"PGU_Zainul Muttaqin.png","link":"https://epsongroup-my.sharepoint.com/personal/brian_ramdhani_epson_co_id/Documents/Apps/Microsoft%20Forms/TAKATSU%20ANALYZE%20REPORT/Question/PGU_Zainul%20Muttaqin.png","id":"01D6UVHSMYKXX5SCFUOFEYYC3ZQ2ZHWNLN","type":null,"size":227599,"referenceId":"01D6UVHSOX5DG5RX522VGYFCV365U3UBU3","driveId":"b!7qg8FsnQY0iiT36_x6Novv_3J9v4MtxPsytkCbb-ZPz3ScQFcxKeSqI2jw7AAtnZ","status":1,"uploadSessionUrl":null}] | U26: https://epsongroup-my.sharepoint.com/personal/brian_ramdhani_epson_co_id/Documents/Apps/Microsoft%20Forms/TAKATSU%20ANALYZE%20REPORT/Question/PGU_Zainul%20Muttaqin.png | V26: vQ_d1TW2GU2umgDs1ysbScgAIkkV | AJ26: Verification in line OK level | AM26: Verification in line OK level | AN26: Zainul Muttaqin
A27: AR241218034332 | C27: 45644 | E27: Takatsu-4 Autocutter | H27: =VLOOKUP(Table1[[#This Row],[Official_Defect_Name]],Sheet2!$A:$F,2,FALSE) -> TKSFE-001 | I27: Fatal Error 205602 | K27: Fatal Error 205602 | L27: =VLOOKUP(Table1[[#This Row],[Official_Defect_Name]],Table3[#All],6,1) -> High | M27: Operator | N27: PG | R27: Saat power on | S27: When Power On at PG Stage, LED ON then OFF and ON again with Error Information System Error 205602 | T27: [{"name":"20241218_160012_Rio Rizki Khanigia.jpg","link":"https://epsongroup-my.sharepoint.com/personal/brian_ramdhani_epson_co_id/Documents/Apps/Microsoft%20Forms/TAKATSU%20ANALYZE%20REPORT/Question/20241218_160012_Rio%20Rizki%20Khanigia.jpg","id":"01D6UVHSKGUDV6UPMORNFJBW5VUKWPC3YO","type":null,"size":2914404,"referenceId":"01D6UVHSOX5DG5RX522VGYFCV365U3UBU3","driveId":"b!7qg8FsnQY0iiT36_x6Novv_3J9v4MtxPsytkCbb-ZPz3ScQFcxKeSqI2jw7AAtnZ","status":1,"uploadSessionUrl":null}] | U27: https://epsongroup-my.sharepoint.com/personal/brian_ramdhani_epson_co_id/Documents/Apps/Microsoft%20Forms/TAKATSU%20ANALYZE%20REPORT/Question/20241218_160012_Rio%20Rizki%20Khanigia.jpg | V27: 7eCIcx8RwE-XdpgZz4nrlMgAAOes | AJ27: Possibility any bug in SD Card, because not any part to Change and Error code information follow to ROM data Saving | AM27: Delete SD Card Serial Number at Tool Menu, then Lock - unlock SD Card from CH77 Main. After that Initial setting at Setting 1 Menu become OK. Temporary monitoring this defect with continue production NG Product from before Stage MA 07 [Internal] | AN27: Rio Rizki Khanigia
A28: AR241218095015 | C28: 45644 | E28: Takatsu-4 Autocutter | H28: =VLOOKUP(Table1[[#This Row],[Official_Defect_Name]],Sheet2!$A:$F,2,FALSE) -> TKSAL-013 | I28: Ink End Sensor NG | K28: Ink End Sensor NG | L28: =VLOOKUP(Table1[[#This Row],[Official_Defect_Name]],Table3[#All],6,1) -> Low | M28: Operator | N28: INTERNAL | R28: Saat proses air leak | S28: When air Leak Check, find Error Information ID 1[10] Check Spring of Ink Holder Unit Error. Ink End Sensor Left NG | T28: [{"name":"20241218_103335_Rio Rizki Khanigia.jpg","link":"https://epsongroup-my.sharepoint.com/personal/brian_ramdhani_epson_co_id/Documents/Apps/Microsoft%20Forms/TAKATSU%20ANALYZE%20REPORT/Question/20241218_103335_Rio%20Rizki%20Khanigia.jpg","id":"01D6UVHSPY4EIZHHEYIJCLJWBXP4C5ILBL","type":null,"size":3013002,"referenceId":"01D6UVHSOX5DG5RX522VGYFCV365U3UBU3","driveId":"b!7qg8FsnQY0iiT36_x6Novv_3J9v4MtxPsytkCbb-ZPz3ScQFcxKeSqI2jw7AAtnZ","status":1,"uploadSessionUrl":null}] | U28: https://epsongroup-my.sharepoint.com/personal/brian_ramdhani_epson_co_id/Documents/Apps/Microsoft%20Forms/TAKATSU%20ANALYZE%20REPORT/Question/20241218_103335_Rio%20Rizki%20Khanigia.jpg | V28: Mm4KxVGtgEmyHJEzTQnv8sgAHHjy | AJ28: Arrangement Harnes AC not Good. [Any 4M man power at MA 06] | AM28: Additional check arrangement harness AC at next stage [MA 07 - Internal Stage] and Re-training OP MA 06 | AN28: Rio Rizki Khanigia
A29: AR241219083807 | C29: 45645 | E29: Takatsu-4 Autocutter | H29: =VLOOKUP(Table1[[#This Row],[Official_Defect_Name]],Sheet2!$A:$F,2,FALSE) -> TKSAL-022 | I29: Printing Noise | K29: Printing Noise | L29: =VLOOKUP(Table1[[#This Row],[Official_Defect_Name]],Table3[#All],6,1) -> Low | M29: Operator | N29: PRINTING | R29: Saat proses louding paper high gloos | S29: During Iinitialize loading paper High Gloss, found noise at Printing Stage | T29: [{"name":"Picture1_Zainul Muttaqin.png","link":"https://epsongroup-my.sharepoint.com/personal/brian_ramdhani_epson_co_id/Documents/Apps/Microsoft%20Forms/TAKATSU%20ANALYZE%20REPORT/Question/Picture1_Zainul%20Muttaqin.png","id":"01D6UVHSIP5BBNY7X47FDKM7NHOR2YMNUL","type":null,"size":120441,"referenceId":"01D6UVHSOX5DG5RX522VGYFCV365U3UBU3","driveId":"b!7qg8FsnQY0iiT36_x6Novv_3J9v4MtxPsytkCbb-ZPz3ScQFcxKeSqI2jw7AAtnZ","status":1,"uploadSessionUrl":null}] | U29: https://epsongroup-my.sharepoint.com/personal/brian_ramdhani_epson_co_id/Documents/Apps/Microsoft%20Forms/TAKATSU%20ANALYZE%20REPORT/Question/Picture1_Zainul%20Muttaqin.png | V29: Wx_4LijQ6kOl-70sW87hfcgAOZbP | AJ29: Retry initialize loading paper bocome OK permanenly 10/10 | AM29: Retry initialize loading paper bocome OK permanenly 10/10 | AN29: Zainul Muttaqin
A30: AR241219120619 | C30: 45645 | E30: Takatsu-4 Autocutter | H30: =VLOOKUP(Table1[[#This Row],[Official_Defect_Name]],Sheet2!$A:$F,2,FALSE) -> TKSAL-002 | I30: Abnormal Noise | K30: Abnormal Noise | L30: =VLOOKUP(Table1[[#This Row],[Official_Defect_Name]],Table3[#All],6,1) -> #N/A | M30: Operator | N30: STG SAFETY | R30: Saat buka tutup cover paper guide | S30: During external check open-close Cover Paper Unit, found noise [Tak-Tak] | T30: [{"name":"Picture3_Zainul Muttaqin.png","link":"https://epsongroup-my.sharepoint.com/personal/brian_ramdhani_epson_co_id/Documents/Apps/Microsoft%20Forms/TAKATSU%20ANALYZE%20REPORT/Question/Picture3_Zainul%20Muttaqin.png","id":"01D6UVHSNNJQXVMHU5QNHIRRKRXWJC53EL","type":null,"size":97885,"referenceId":"01D6UVHSOX5DG5RX522VGYFCV365U3UBU3","driveId":"b!7qg8FsnQY0iiT36_x6Novv_3J9v4MtxPsytkCbb-ZPz3ScQFcxKeSqI2jw7AAtnZ","status":1,"uploadSessionUrl":null}] | U30: https://epsongroup-my.sharepoint.com/personal/brian_ramdhani_epson_co_id/Documents/Apps/Microsoft%20Forms/TAKATSU%20ANALYZE%20REPORT/Question/Picture3_Zainul%20Muttaqin.png | V30: XnKZSbM9x0qI8yMW4bBxNMgAHOww | AJ30: Reassembly HOLDER,HINGE FIXED,FRONT become OK, possibility occured due to assembly problem | AM30: Review assembly related stage, continue monitoring this defect | AN30: Zainul Muttaqin
A31: AR241220090330 | C31: 45646 | E31: Takatsu-4 Autocutter | H31: =VLOOKUP(Table1[[#This Row],[Official_Defect_Name]],Sheet2!$A:$F,2,FALSE) -> TKSAL-017 | I31: Paper Jam | K31: Paper Jam | L31: =VLOOKUP(Table1[[#This Row],[Official_Defect_Name]],Table3[#All],6,1) -> Low | M31: Operator | N31: PRINTING | R31: Saat proses calibrasi | S31: During calibration process using APMP Paper, found Paper Jam | T31: [{"name":"Paper Jam1_Zainul Muttaqin.jpg","link":"https://epsongroup-my.sharepoint.com/personal/brian_ramdhani_epson_co_id/Documents/Apps/Microsoft%20Forms/TAKATSU%20ANALYZE%20REPORT/Question/Paper%20Jam1_Zainul%20Muttaqin.jpg","id":"01D6UVHSJ4ZDDUHTFLW5AZA7G7PMHTNX56","type":null,"size":136918,"referenceId":"01D6UVHSOX5DG5RX522VGYFCV365U3UBU3","driveId":"b!7qg8FsnQY0iiT36_x6Novv_3J9v4MtxPsytkCbb-ZPz3ScQFcxKeSqI2jw7AAtnZ","status":1,"uploadSessionUrl":null}] | U31: https://epsongroup-my.sharepoint.com/personal/brian_ramdhani_epson_co_id/Documents/Apps/Microsoft%20Forms/TAKATSU%20ANALYZE%20REPORT/Question/Paper%20Jam1_Zainul%20Muttaqin.jpg | V31: ZCuAS7HOckyG8OCYCF00IsgAMWi0 | AJ31: OPR pressing leaf spring during assembly to FRAME PF R and FRAME PF L | AM31: 1. Retraining and reminding OPR so as not to add to the pressing process during assembly leaf spring, 2. OPR must be follow ALO how to calibration process with APMP Paper | AN31: Zainul Muttaqin
A32: AR241223033156 | C32: 45649 | E32: Takatsu-4 Autocutter | H32: =VLOOKUP(Table1[[#This Row],[Official_Defect_Name]],Sheet2!$A:$F,2,FALSE) -> TKSAL-009 | I32: DMAV | K32: DMAV | L32: =VLOOKUP(Table1[[#This Row],[Official_Defect_Name]],Table3[#All],6,1) -> Severity | M32: Operator | N32: PRINTING | R32: Jig 02 | S32: During nozzle check at Printing Stage, found DMAV [F1,180] | T32: [{"name":"20241224_085753_Zainul Muttaqin.jpg","link":"https://epsongroup-my.sharepoint.com/personal/brian_ramdhani_epson_co_id/Documents/Apps/Microsoft%20Forms/TAKATSU%20ANALYZE%20REPORT/Question/20241224_085753_Zainul%20Muttaqin.jpg","id":"01D6UVHSJGVVC3XN267FBYWPXD4SGCGQPO","type":null,"size":2149299,"referenceId":"01D6UVHSOX5DG5RX522VGYFCV365U3UBU3","driveId":"b!7qg8FsnQY0iiT36_x6Novv_3J9v4MtxPsytkCbb-ZPz3ScQFcxKeSqI2jw7AAtnZ","status":1,"uploadSessionUrl":null}] | U32: https://epsongroup-my.sharepoint.com/personal/brian_ramdhani_epson_co_id/Documents/Apps/Microsoft%20Forms/TAKATSU%20ANALYZE%20REPORT/Question/20241224_085753_Zainul%20Muttaqin.jpg | V32: 6GSHTCRXzEi5WQghffBpJ8gAJv4H | AJ32: Still Analyze | AM32: To be continue wiping and cleaning | AN32: Zainul Muttaqin
... A35: AR250102010320 | C35: 45659 | E35: Takatsu-8 Autocutter | H35: =VLOOKUP(Table1[[#This Row],[Official_Defect_Name]],Sheet2!$A:$F,2,FALSE) -> TKSAL-025 | I35: Shutter Check Noise | K35: Shutter Check Noise | L35: =VLOOKUP(Table1[[#This Row],[Official_Defect_Name]],Table3[#All],6,1) -> Low | M35: Operator | N35: PG | R35: Noise saat proses shutter cek | S35: During shutter check inspection at PG stage, found noise (Judgement by OPR) | T35: [{"name":"Shutter check noise_Zainul Muttaqin.png","link":"https://epsongroup-my.sharepoint.com/personal/brian_ramdhani_epson_co_id/Documents/Apps/Microsoft%20Forms/TAKATSU%20ANALYZE%20REPORT/Question/Shutter%20check%20noise_Zainul%20Muttaqin.png","id":"01D6UVHSI2K37B4SUMGFALLARG5WR4PNTO","type":null,"size":170890,"referenceId":"01D6UVHSOX5DG5RX522VGYFCV365U3UBU3","driveId":"b!7qg8FsnQY0iiT36_x6Novv_3J9v4MtxPsytkCbb-ZPz3ScQFcxKeSqI2jw7AAtnZ","status":1,"uploadSessionUrl":null}] | U35: https://epsongroup-my.sharepoint.com/personal/brian_ramdhani_epson_co_id/Documents/Apps/Microsoft%20Forms/TAKATSU%20ANALYZE%20REPORT/Question/Shutter%20check%20noise_Zainul%20Muttaqin.png | V35: ZkYwdsffR0yjw2fYc3qb98gAHBKk | AJ35: Retry in line OK, over judgement | AM35: Retry in line OK, over judgement | AN35: Zainul Muttaqin
A36: AR250102103216 | C36: 45659 | E36: Takatsu-8 Autocutter | H36: =VLOOKUP(Table1[[#This Row],[Official_Defect_Name]],Sheet2!$A:$F,2,FALSE) -> TKSAL-025 | I36: Shutter Check Noise | K36: Shutter Check Noise | L36: =VLOOKUP(Table1[[#This Row],[Official_Defect_Name]],Table3[#All],6,1) -> Low | M36: Operator | N36: STG PG | R36: Saat proses shutter cek | V36: 67fzNfu62EmQq9_ACR5aB8gAM7jK
A37: AR250103010659 | C37: 45660 | E37: Takatsu-8 Peeler | H37: =VLOOKUP(Table1[[#This Row],[Official_Defect_Name]],Sheet2!$A:$F,2,FALSE) -> TKSAL-009 | I37: DMAV | K37: DMAV | L37: =VLOOKUP(Table1[[#This Row],[Official_Defect_Name]],Table3[#All],6,1) -> Severity | M37: Operator | N37: PRINTING | R37: Jig 07 | S37: DMAV | T37: [{"name":"DMAV 3 jan_Nazar Bagus H..jpg","link":"https://epsongroup-my.sharepoint.com/personal/brian_ramdhani_epson_co_id/Documents/Apps/Microsoft%20Forms/TAKATSU%20ANALYZE%20REPORT/Question/DMAV%203%20jan_Nazar%20Bagus%20H..jpg","id":"01D6UVHSN5LVJYTXL5ZRHLBIH4IVBUTZC5","type":null,"size":55728,"referenceId":"01D6UVHSOX5DG5RX522VGYFCV365U3UBU3","driveId":"b!7qg8FsnQY0iiT36_x6Novv_3J9v4MtxPsytkCbb-ZPz3ScQFcxKeSqI2jw7AAtnZ","status":1,"uploadSessionUrl":null}] | U37: https://epsongroup-my.sharepoint.com/personal/brian_ramdhani_epson_co_id/Documents/Apps/Microsoft%20Forms/TAKATSU%20ANALYZE%20REPORT/Question/DMAV%203%20jan_Nazar%20Bagus%20H..jpg | V37: r8ym3dZfDk63fG9AsDGHp8gALbtn | AJ37: Possibility any foreign material on surface PH | AM37: Wiping PH can recovery | AN37: Nazar Bagus H.
A38: AR250103104018 | C38: 45660 | E38: Takatsu-8 Autocutter | H38: =VLOOKUP(Table1[[#This Row],[Official_Defect_Name]],Sheet2!$A:$F,2,FALSE) -> TKSAL-010 | I38: DO | K38: DO | L38: =VLOOKUP(Table1[[#This Row],[Official_Defect_Name]],Table3[#All],6,1) -> Critical | M38: Operator | N38: PRINTING | R38: Jig 02 | V38: OZi668R6FEWwH-Al0OwIJ8gAL5e7
A39: AR250109014020 | C39: 45666 | E39: Takatsu-8 Autocutter | H39: =VLOOKUP(Table1[[#This Row],[Official_Defect_Name]],Sheet2!$A:$F,2,FALSE) -> TKSAL-025 | I39: Shutter Check Noise | K39: Shutter Check Noise | L39: =VLOOKUP(Table1[[#This Row],[Official_Defect_Name]],Table3[#All],6,1) -> Low | M39: Operator | N39: PG | R39: Saat proses shutter cek | S39: During Shutter check any small noise | T39: [{"name":"False Reject_Nazar Bagus H..PNG","link":"https://epsongroup-my.sharepoint.com/personal/brian_ramdhani_epson_co_id/Documents/Apps/Microsoft%20Forms/TAKATSU%20ANALYZE%20REPORT/Question/False%20Reject_Nazar%20Bagus%20H..PNG","id":"01D6UVHSNGIEMFSJ3H7NH2XUVOTXAICOBF","type":null,"size":1313,"referenceId":"01D6UVHSOX5DG5RX522VGYFCV365U3UBU3","driveId":"b!7qg8FsnQY0iiT36_x6Novv_3J9v4MtxPsytkCbb-ZPz3ScQFcxKeSqI2jw7AAtnZ","status":1,"uploadSessionUrl":null}] | U39: https://epsongroup-my.sharepoint.com/personal/brian_ramdhani_epson_co_id/Documents/Apps/Microsoft%20Forms/TAKATSU%20ANALYZE%20REPORT/Question/False%20Reject_Nazar%20Bagus%20H..PNG | V39: bAbiyrmbzUSzQGwDUxjj3sgALzR9 | AJ39: Not NG | AM39: Continue Inspection | AN39: Nazar Bagus H.
A40: AR250109014242 | C40: 45666 | E40: Takatsu-8 Autocutter | H40: =VLOOKUP(Table1[[#This Row],[Official_Defect_Name]],Sheet2!$A:$F,2,FALSE) -> TKSAL-004 | I40: Abnormal PGU Movement | K40: Abnormal PGU Movement | L40: =VLOOKUP(Table1[[#This Row],[Official_Defect_Name]],Table3[#All],6,1) -> #N/A | M40: Operator | N40: STG PH 2 | R40: - | S40: PGU seret sedikit, tidak separah yang kemarin | T40: [{"name":"False Reject_Nazar Bagus H. 1.PNG","link":"https://epsongroup-my.sharepoint.com/personal/brian_ramdhani_epson_co_id/Documents/Apps/Microsoft%20Forms/TAKATSU%20ANALYZE%20REPORT/Question/False%20Reject_Nazar%20Bagus%20H.%201.PNG","id":"01D6UVHSN7TFOGML7NBJHZJQZD7M4GKFFC","type":null,"size":1313,"referenceId":"01D6UVHSOX5DG5RX522VGYFCV365U3UBU3","driveId":"b!7qg8FsnQY0iiT36_x6Novv_3J9v4MtxPsytkCbb-ZPz3ScQFcxKeSqI2jw7AAtnZ","status":1,"uploadSessionUrl":null}] | U40: https://epsongroup-my.sharepoint.com/personal/brian_ramdhani_epson_co_id/Documents/Apps/Microsoft%20Forms/TAKATSU%20ANALYZE%20REPORT/Question/False%20Reject_Nazar%20Bagus%20H.%201.PNG | V40: tPxO08RSCUie_kYQtiEZZ8gAJ9BP | AJ40: Frame Base | AM40: Addition Lumirar di JIG Frame Base | AN40: Nazar Bagus H.
A41: AR250110015639 | C41: 45667 | E41: Takatsu-4 Autocutter | H41: =VLOOKUP(Table1[[#This Row],[Official_Defect_Name]],Sheet2!$A:$F,2,FALSE) -> TKSAL-007 | I41: CSIC Check NG | K41: CSIC Check NG | L41: =VLOOKUP(Table1[[#This Row],[Official_Defect_Name]],Table3[#All],6,1) -> #N/A | M41: Operator | N41: PG | R41: Saat proses power on | S41: During initial power ON product, panel shown [MTC Box not installed] | T41: [{"name":"FFC MTC Tear_Zainul Muttaqin.png","link":"https://epsongroup-my.sharepoint.com/personal/brian_ramdhani_epson_co_id/Documents/Apps/Microsoft%20Forms/TAKATSU%20ANALYZE%20REPORT/Question/FFC%20MTC%20Tear_Zainul%20Muttaqin.png","id":"01D6UVHSM3YQX5DL4JKBAJ7M25THKT2GE5","type":null,"size":617652,"referenceId":"01D6UVHSOX5DG5RX522VGYFCV365U3UBU3","driveId":"b!7qg8FsnQY0iiT36_x6Novv_3J9v4MtxPsytkCbb-ZPz3ScQFcxKeSqI2jw7AAtnZ","status":1,"uploadSessionUrl":null}] | U41: https://epsongroup-my.sharepoint.com/personal/brian_ramdhani_epson_co_id/Documents/Apps/Microsoft%20Forms/TAKATSU%20ANALYZE%20REPORT/Question/FFC%20MTC%20Tear_Zainul%20Muttaqin.png | V41: L3Zw2lCl6UWUxgccMUMUk8gACx5m | AJ41: FFC holder MTC Box was tear occured due to assembly by OPR | AM41: Reminding and retraining OPR, must follow checkpoint on SWP during assembly FFC | AN41: Zainul Muttaqin
A42: AR250110031035 | C42: 45667 | E42: Takatsu-8 Autocutter | H42: =VLOOKUP(Table1[[#This Row],[Official_Defect_Name]],Sheet2!$A:$F,2,FALSE) -> TKSAL-018 | I42: Peeler Measurement NG | K42: Peeler Measurement NG | L42: =VLOOKUP(Table1[[#This Row],[Official_Defect_Name]],Table3[#All],6,1) -> Low | M42: Operator | N42: PG | R42: Saat proses peeler measurment | S42: During peeler measurement check, found the current results below standard | T42: [{"name":"Peeler Measurement NG_Zainul Muttaqin.png","link":"https://epsongroup-my.sharepoint.com/personal/brian_ramdhani_epson_co_id/Documents/Apps/Microsoft%20Forms/TAKATSU%20ANALYZE%20REPORT/Question/Peeler%20Measurement%20NG_Zainul%20Muttaqin.png","id":"01D6UVHSIMZCTOHUQMDNC3YTQXGUOQMTDQ","type":null,"size":266538,"referenceId":"01D6UVHSOX5DG5RX522VGYFCV365U3UBU3","driveId":"b!7qg8FsnQY0iiT36_x6Novv_3J9v4MtxPsytkCbb-ZPz3ScQFcxKeSqI2jw7AAtnZ","status":1,"uploadSessionUrl":null}] | U42: https://epsongroup-my.sharepoint.com/personal/brian_ramdhani_epson_co_id/Documents/Apps/Microsoft%20Forms/TAKATSU%20ANALYZE%20REPORT/Question/Peeler%20Measurement%20NG_Zainul%20Muttaqin.png | V42: 6vs-HQIzJk6vUILBomOeTsgACmvC | AJ42: Belt tension too loose adjustment by OPR | AM42: Re-adjustment belt tension by OPR become OK | AN42: Zainul Muttaqin
...

Sheet Sheet2
A1: Defect_Name | B1: Def_ID | C1: Total_Qty | D1: Percentage | E1: Task_ID | F1: Severity | G1: =SUM(C:C) -> 251
A2: DO | B2: TKSAL-010 | C2: =COUNTIF(Table1[Def_ID],B2) -> 29 | D2: =C2/$G$1 -> 0.11553785 | E2: MFd0s0c60UuKz9gykctZ9MgAFpL- | F2: =IF(AND(D2>3%,D2<10%),"High",IF(D2>10%,"Critical","Low")) -> Critical
A3: Abnormal Noise | B3: TKSAL-002 | C3: =COUNTIF(Table1[Def_ID],B3) -> 23 | D3: =C3/$G$1 -> 0.091633466 | F3: =IF(AND(D3>3%,D3<10%),"High",IF(D3>10%,"Critical","Low")) -> High
A4: DMAV | B4: TKSAL-009 | C4: =COUNTIF(Table1[Def_ID],B4) -> 19 | D4: =C4/$G$1 -> 0.075697211 | F4: =IF(AND(D4>3%,D4<10%),"High",IF(D4>10%,"Critical","Low")) -> High
A5: Paper Jam | B5: TKSAL-017 | C5: =COUNTIF(Table1[Def_ID],B5) -> 19 | D5: =C5/$G$1 -> 0.075697211 | F5: =IF(AND(D5>3%,D5<10%),"High",IF(D5>10%,"Critical","Low")) -> High
A6: Unstable Printing | B6: TKSAL-027 | C6: =COUNTIF(Table1[Def_ID],B6) -> 17 | D6: =C6/$G$1 -> 0.067729084 | F6: =IF(AND(D6>3%,D6<10%),"High",IF(D6>10%,"Critical","Low")) -> High
A7: Abnormal Power On | B7: TKSAL-005 | C7: =COUNTIF(Table1[Def_ID],B7) -> 13 | D7: =C7/$G$1 -> 0.051792829 | F7: =IF(AND(D7>3%,D7<10%),"High",IF(D7>10%,"Critical","Low")) -> High
A8: Abnormal PGU Movement | B8: TKSAL-004 | C8: =COUNTIF(Table1[Def_ID],B8) -> 11 | D8: =C8/$G$1 -> 0.043824701 | E8: 2Bxf-I2UBU2DtuoOzc2cjMgAGyar | F8: =IF(AND(D8>3%,D8<10%),"High",IF(D8>10%,"Critical","Low")) -> High
A9: Printing Noise | B9: TKSAL-022 | C9: =COUNTIF(Table1[Def_ID],B9) -> 10 | D9: =C9/$G$1 -> 0.039840637 | F9: =IF(AND(D9>3%,D9<10%),"High",IF(D9>10%,"Critical","Low")) -> High
A10: Shutter Check Noise | B10: TKSAL-025 | C10: =COUNTIF(Table1[Def_ID],B10) -> 10 | D10: =C10/$G$1 -> 0.039840637 | F10: =IF(AND(D10>3%,D10<10%),"High",IF(D10>10%,"Critical","Low")) -> High
A11: Fatal Error 5853 | B11: TKSFE-007 | C11: =COUNTIF(Table1[Def_ID],B11) -> 9 | D11: =C11/$G$1 -> 0.035856574 | F11: =IF(AND(D11>3%,D11<10%),"High",IF(D11>10%,"Critical","Low")) -> High
A12: No Power | B12: TKSAL-016 | C12: =COUNTIF(Table1[Def_ID],B12) -> 8 | D12: =C12/$G$1 -> 0.03187251 | F12: =IF(AND(D12>3%,D12<10%),"High",IF(D12>10%,"Critical","Low")) -> High
A13: Ink End Sensor NG | B13: TKSAL-013 | C13: =COUNTIF(Table1[Def_ID],B13) -> 8 | D13: =C13/$G$1 -> 0.03187251 | F13: =IF(AND(D13>3%,D13<10%),"High",IF(D13>10%,"Critical","Low")) -> High
A14: Initial Setting NG | B14: TKSAL-011 | C14: =COUNTIF(Table1[Def_ID],B14) -> 8 | D14: =C14/$G$1 -> 0.03187251 | F14: =IF(AND(D14>3%,D14<10%),"High",IF(D14>10%,"Critical","Low")) -> High
A15: Abnormal Paper Loading | B15: TKSAL-003 | C15: =COUNTIF(Table1[Def_ID],B15) -> 7 | D15: =C15/$G$1 -> 0.027888446 | F15: =IF(AND(D15>3%,D15<10%),"High",IF(D15>10%,"Critical","Low")) -> Low
A16: CSIC Check NG | B16: TKSAL-007 | C16: =COUNTIF(Table1[Def_ID],B16) -> 7 | D16: =C16/$G$1 -> 0.027888446 | F16: =IF(AND(D16>3%,D16<10%),"High",IF(D16>10%,"Critical","Low")) -> Low
A17: DMAH | B17: TKSAL-008 | C17: =COUNTIF(Table1[Def_ID],B17) -> 7 | D17: =C17/$G$1 -> 0.027888446 | F17: =IF(AND(D17>3%,D17<10%),"High",IF(D17>10%,"Critical","Low")) -> Low
A18: CR Measurement NG | B18: TKSAL-006 | C18: =COUNTIF(Table1[Def_ID],B18) -> 6 | D18: =C18/$G$1 -> 0.023904382 | F18: =IF(AND(D18>3%,D18<10%),"High",IF(D18>10%,"Critical","Low")) -> Low
A19: Peeler Measurement NG | B19: TKSAL-018 | C19: =COUNTIF(Table1[Def_ID],B19) -> 4 | D19: =C19/$G$1 -> 0.015936255 | F19: =IF(AND(D19>3%,D19<10%),"High",IF(D19>10%,"Critical","Low")) -> Low
A20: Smear Print | B20: TKSAL-026 | C20: =COUNTIF(Table1[Def_ID],B20) -> 4 | D20: =C20/$G$1 -> 0.015936255 | F20: =IF(AND(D20>3%,D20<10%),"High",IF(D20>10%,"Critical","Low")) -> Low
... A41: Fatal Error 5834 | B41: TKSFE-008 | C41: =COUNTIF(Table1[Def_ID],B41) -> 0 | D41: =C41/$G$1 -> 0 | F41: =IF(AND(D41>3%,D41<10%),"High",IF(D41>10%,"Critical","Low")) -> Low
C42: =COUNTIF(Table1[Def_ID],B42) -> 0 | D42: =C42/$G$1 -> 0
C43: =COUNTIF(Table1[Def_ID],B43) -> 0 | D43: =C43/$G$1 -> 0
C44: =COUNTIF(Table1[Def_ID],B44) -> 0 | D44: =C44/$G$1 -> 0
C45: =COUNTIF(Table1[Def_ID],B45) -> 0 | D45: =C45/$G$1 -> 0
C46: =COUNTIF(Table1[Def_ID],B46) -> 0 | D46: =C46/$G$1 -> 0

Sheet Sheet3
A1: RCA No | B1: Request No | C1: Date_of_Request | D1: Date_of_Report | E1: Model | F1: Def_ID | G1: Official_Defect_Name | H1: Defect Name | I1: Severity_Level | J1: Detect_By | K1: Stage | L1: During_Process | M1: How_Much | N1: Main_Impact | O1: Phenomenon | P1: Verify Phenomenon | Q1: Link Photo of Phenomenon | R1: Url Photo | S1: Task Id | T1: Analyze_Process | U1: Part_Replacement | V1: 4M_Potential_Cause | W1: 5-Why_Analyze | X1: Root Cause | Y1: Corrective_Action | Z1: Preventive_Action | AA1: Action Item | AB1: Created By
B2: AR250106074235 | C2: 45663 | E2: Takatsu-8 Peeler | F2: TKSAL-023 | G2: Printing Skew | H2: Printing Skew | I2: Low | J2: Operator | K2: STG PRINTING | O2: Jig 05 | P2: Skew during printing on peeler | Q2: [{"name":"skew printing_Nazar Bagus H..png","link":"https://epsongroup-my.sharepoint.com/personal/brian_ramdhani_epson_co_id/Documents/Apps/Microsoft%20Forms/TAKATSU%20ANALYZE%20REPORT/Question/skew%20printing_Nazar%20Bagus%20H..png","id":"01D6UVHSPS33Y4BWTZFBEKYB65OMZCSYMN","type":null,"size":263423,"referenceId":"01D6UVHSOX5DG5RX522VGYFCV365U3UBU3","driveId":"b!7qg8FsnQY0iiT36_x6Novv_3J9v4MtxPsytkCbb-ZPz3ScQFcxKeSqI2jw7AAtnZ","status":1,"uploadSessionUrl":null}] | R2: https://epsongroup-my.sharepoint.com/personal/brian_ramdhani_epson_co_id/Documents/Apps/Microsoft%20Forms/TAKATSU%20ANALYZE%20REPORT/Question/skew%20printing_Nazar%20Bagus%20H..png | S2: dHrh6qQXjUi6VDHBsF4FJcgADdUe | X2: Frame Peeler Char CL&CM NG | AA2: Temporary bending manually frame peeler until OK. Permanent A/I improve char | AB2: Nazar Bagus H.
B3: AR250106080119 | C3: 45663 | E3: Takatsu-8 Peeler | F3: TKSAL-023 | G3: Printing Skew | H3: Printing Skew | I3: Low | J3: Operator | K3: PRINTING | O3: Jig 01 | P3: Skew during printing on peeler | Q3: [{"name":"skew printing_Nazar Bagus H. 1.png","link":"https://epsongroup-my.sharepoint.com/personal/brian_ramdhani_epson_co_id/Documents/Apps/Microsoft%20Forms/TAKATSU%20ANALYZE%20REPORT/Question/skew%20printing_Nazar%20Bagus%20H.%201.png","id":"01D6UVHSMIQONQT5OK6JE3UY7UG3GF4ZYM","type":null,"size":263423,"referenceId":"01D6UVHSOX5DG5RX522VGYFCV365U3UBU3","driveId":"b!7qg8FsnQY0iiT36_x6Novv_3J9v4MtxPsytkCbb-ZPz3ScQFcxKeSqI2jw7AAtnZ","status":1,"uploadSessionUrl":null}] | R3: https://epsongroup-my.sharepoint.com/personal/brian_ramdhani_epson_co_id/Documents/Apps/Microsoft%20Forms/TAKATSU%20ANALYZE%20REPORT/Question/skew%20printing_Nazar%20Bagus%20H.%201.png | S3: wGCa2G6fmECO0uLonVNv2cgADOZq | X3: Frame Peeler char CL&CM NG | AA3: Bending Manually until OK. Temporary A/I improve char CL&CM | AB3: Nazar Bagus H.
B4: AR250110113540 | C4: 45667 | E4: Takatsu-8 Peeler | F4: TKSAL-023 | G4: Printing Skew | H4: Printing Skew | I4: Low | J4: Operator | K4: PRINTING | O4: Saat proses print 3,5(1st) | P4: During paper loading with print menu 3.5 (1st), found paper become floating | Q4: [{"name":"Abnormal Loading_Zainul Muttaqin.png","link":"https://epsongroup-my.sharepoint.com/personal/brian_ramdhani_epson_co_id/Documents/Apps/Microsoft%20Forms/TAKATSU%20ANALYZE%20REPORT/Question/Abnormal%20Loading_Zainul%20Muttaqin.png","id":"01D6UVHSJOGD2P25AVKNAYQ56PA46WKLW3","type":null,"size":166771,"referenceId":"01D6UVHSOX5DG5RX522VGYFCV365U3UBU3","driveId":"b!7qg8FsnQY0iiT36_x6Novv_3J9v4MtxPsytkCbb-ZPz3ScQFcxKeSqI2jw7AAtnZ","status":1,"uploadSessionUrl":null}] | R4: https://epsongroup-my.sharepoint.com/personal/brian_ramdhani_epson_co_id/Documents/Apps/Microsoft%20Forms/TAKATSU%20ANALYZE%20REPORT/Question/Abnormal%20Loading_Zainul%20Muttaqin.png | S4: qfacB2nhRkuSYIwArCR37sgAPS1b | X4: Sheet peeler antistatic not neat, assembly by OPR | AA4: Reminding and retraining OPR must be follow SWP dueing assembly | AB4: Zainul Muttaqin
B5: AR250203014425 | C5: 45691 | E5: Takatsu-4 Autocutter | F5: TKSAL-023 | G5: Printing Skew | H5: Printing Skew | I5: Low | J5: Operator | K5: PRINTING | O5: Jig 05 -- produk after change ph | P5: During Head Incline, Value NG Max | Q5: [{"name":"False Reject_Nazar Bagus H. 2.PNG","link":"https://epsongroup-my.sharepoint.com/personal/brian_ramdhani_epson_co_id/Documents/Apps/Microsoft%20Forms/TAKATSU%20ANALYZE%20REPORT/Question/False%20Reject_Nazar%20Bagus%20H.%202.PNG","id":"01D6UVHSN4AIP4MBZAENE2H6MHOAG37II7","type":null,"size":1313,"referenceId":"01D6UVHSOX5DG5RX522VGYFCV365U3UBU3","driveId":"b!7qg8FsnQY0iiT36_x6Novv_3J9v4MtxPsytkCbb-ZPz3ScQFcxKeSqI2jw7AAtnZ","status":1,"uploadSessionUrl":null}] | R5: https://epsongroup-my.sharepoint.com/personal/brian_ramdhani_epson_co_id/Documents/Apps/Microsoft%20Forms/TAKATSU%20ANALYZE%20REPORT/Question/False%20Reject_Nazar%20Bagus%20H.%202.PNG | S5: Nd-XY6bdEeJyhP-MzEQNsgAKXmV | X5: Operator at Stage Print Head not Reset Dial Katamuki Position after change print Head | AA5: Re-Assy Print Head become OK | AB5: Nazar Bagus H.
B6: AR250203113905 | C6: 45691 | E6: Takatsu-8 Peeler | F6: TKSAL-023 | G6: Printing Skew | H6: Printing Skew | I6: Low | J6: Operator | K6: PRINTING | O6: Saat print cek 3,5 (1st) | P6: During the printer was run with menu print check 3.5, found 1st dot NG | Q6: [{"name":"1st dot_Zainul Muttaqin.png","link":"https://epsongroup-my.sharepoint.com/personal/brian_ramdhani_epson_co_id/Documents/Apps/Microsoft%20Forms/TAKATSU%20ANALYZE%20REPORT/Question/1st%20dot_Zainul%20Muttaqin.png","id":"01D6UVHSJJ75CFSUUBHZH2NZPECQCIPMIC","type":null,"size":78082,"referenceId":"01D6UVHSOX5DG5RX522VGYFCV365U3UBU3","driveId":"b!7qg8FsnQY0iiT36_x6Novv_3J9v4MtxPsytkCbb-ZPz3ScQFcxKeSqI2jw7AAtnZ","status":1,"uploadSessionUrl":null}] | R6: https://epsongroup-my.sharepoint.com/personal/brian_ramdhani_epson_co_id/Documents/Apps/Microsoft%20Forms/TAKATSU%20ANALYZE%20REPORT/Question/1st%20dot_Zainul%20Muttaqin.png | S6: aGi3e64uyk-gM4CV9cSnBsgAGj6e | X6: Measurement plat peeler with Dial Gauge more than 0.03 mm [SA] | AA6: Retraining and reminding OPR, to ensure must be calibration [left 0, right 0] before use dial indicator. | AB6: Zainul Muttaqin
B7: AR250204090748 | C7: 45692 | E7: Takatsu-8 Peeler | F7: TKSAL-023 | G7: Printing Skew | H7: Printing Skew | I7: Low | J7: Operator | K7: PRINTING | O7: Saat proses print 3,5(2nd) | P7: Paper Skew During Print Check 3.5 1st | Q7: [{"name":"Peeler Open not_Nazar Bagus H..jpg","link":"https://epsongroup-my.sharepoint.com/personal/brian_ramdhani_epson_co_id/Documents/Apps/Microsoft%20Forms/TAKATSU%20ANALYZE%20REPORT/Question/Peeler%20Open%20not_Nazar%20Bagus%20H..jpg","id":"01D6UVHSL3GGCD5FGF2FF2FKIX44NFXKBP","type":null,"size":17798,"referenceId":"01D6UVHSOX5DG5RX522VGYFCV365U3UBU3","driveId":"b!7qg8FsnQY0iiT36_x6Novv_3J9v4MtxPsytkCbb-ZPz3ScQFcxKeSqI2jw7AAtnZ","status":1,"uploadSessionUrl":null}] | R7: https://epsongroup-my.sharepoint.com/personal/brian_ramdhani_epson_co_id/Documents/Apps/Microsoft%20Forms/TAKATSU%20ANALYZE%20REPORT/Question/Peeler%20Open%20not_Nazar%20Bagus%20H..jpg | S7: sPBYuawugEqM2UcaOfGuG8gADVCk | X7: Peeler Press Unit Not screwed properly | AA7: Change Peeler Press with fresh Part become OK | AB7: Nazar Bagus H.
B8: AR250204110823 | C8: 45692 | E8: Takatsu-4 Peeler | F8: TKSAL-023 | G8: Printing Skew | H8: Printing Skew | I8: Low | J8: Operator | K8: PRINTING | O8: Jig 1 | S8: IcCrn0ei-0SQnU8q3wY8q8gADSno
B9: AR250205044454 | C9: 45693 | E9: Takatsu-8 Autocutter | F9: TKSAL-023 | G9: Printing Skew | H9: Printing Skew | I9: Low | J9: Operator | K9: Printing | O9: Jig 08 | P9: When roll paper loading, paper hit Edge of Plate platen and find paper curl | Q9: [{"name":"Plate Platen Bending_Rio Rizki Khanigia.jpg","link":"https://epsongroup-my.sharepoint.com/personal/brian_ramdhani_epson_co_id/Documents/Apps/Microsoft%20Forms/TAKATSU%20ANALYZE%20REPORT/Question/Plate%20Platen%20Bending_Rio%20Rizki%20Khanigia.jpg","id":"01D6UVHSP7AEEGGZSYWNBLUZ2UUQPPFUB5","type":null,"size":113355,"referenceId":"01D6UVHSOX5DG5RX522VGYFCV365U3UBU3","driveId":"b!7qg8FsnQY0iiT36_x6Novv_3J9v4MtxPsytkCbb-ZPz3ScQFcxKeSqI2jw7AAtnZ","status":1,"uploadSessionUrl":null}] | R9: https://epsongroup-my.sharepoint.com/personal/brian_ramdhani_epson_co_id/Documents/Apps/Microsoft%20Forms/TAKATSU%20ANALYZE%20REPORT/Question/Plate%20Platen%20Bending_Rio%20Rizki%20Khanigia.jpg | S9: CxD9uB33i0SOIAMMAVLx7MgACF-m | X9: Plate Platen Bending around 1-2 degree | AA9: Change Palte Platen. Segregate Plate platen Stock main assy, result Pn/n [0/22]. Tomorrow feedback to Part Eng to guarantee Stock part at IEI and Vendor. | AB9: Rio Rizki Khanigia
B10: AR241126094933 | C10: 45622 | E10: Takatsu-8 Autocutter | F10: TKSAL-021 | G10: Platen Fan Adjustment NG | H10: Platen Fan Adjustment NG | I10: Low | J10: Operator | K10: PG | O10: Saat proses pg
B11: AR241204091829 | C11: 45630 | E11: Takatsu-4 Autocutter | F11: TKSAL-021 | G11: Platen Fan Adjustment NG | H11: Platen Fan Adjustment NG | I11: Low | J11: Operator | K11: PG | O11: Saat proses no 4 (platen fan adjusment) | P11: Not enough Suction During Platen Fan Adjustment Check, | Q11: [{"name":"Packing Upper deform_Nazar Bagus H..jpg","link":"https://epsongroup-my.sharepoint.com/personal/brian_ramdhani_epson_co_id/Documents/Apps/Microsoft%20Forms/TAKATSU%20ANALYZE%20REPORT/Question/Packing%20Upper%20deform_Nazar%20Bagus%20H..jpg","id":"01D6UVHSJI4IIMJNN75VB2N7GJBUBPM2FY","type":null,"size":93787,"referenceId":"01D6UVHSOX5DG5RX522VGYFCV365U3UBU3","driveId":"b!7qg8FsnQY0iiT36_x6Novv_3J9v4MtxPsytkCbb-ZPz3ScQFcxKeSqI2jw7AAtnZ","status":1,"uploadSessionUrl":null}] | R11: https://epsongroup-my.sharepoint.com/personal/brian_ramdhani_epson_co_id/Documents/Apps/Microsoft%20Forms/TAKATSU%20ANALYZE%20REPORT/Question/Packing%20Upper%20deform_Nazar%20Bagus%20H..jpg | S11: L28Pd-mtOkqE84h-4bXaxcgAPKA_ | X11: Packing Upper deform after Change Platen Unit (Previously NG Paper Jam and Change Platen Unit) | AA11: Re Form Packing Upper and retry in Line --> Result OK | AB11: Nazar Bagus H.
B12: AR250108022137 | C12: 45665 | E12: Takatsu-8 Autocutter | F12: TKSAL-021 | G12: Platen Fan Adjustment NG | H12: Platen Fan Adjustment NG | I12: Low | J12: Operator | K12: PG | O12: Platen fan adjusment | P12: During Platen Fan Adjustment, value NG Minimum | Q12: [{"name":"Platen Fan NG, Platen Gap_Nazar Bagus H..jpg","link":"https://epsongroup-my.sharepoint.com/personal/brian_ramdhani_epson_co_id/Documents/Apps/Microsoft%20Forms/TAKATSU%20ANALYZE%20REPORT/Question/Platen%20Fan%20NG,%20Platen%20Gap_Nazar%20Bagus%20H..jpg","id":"01D6UVHSL2J3ZKK4LR35HKH4GBACKK7NJZ","type":null,"size":55574,"referenceId":"01D6UVHSOX5DG5RX522VGYFCV365U3UBU3","driveId":"b!7qg8FsnQY0iiT36_x6Novv_3J9v4MtxPsytkCbb-ZPz3ScQFcxKeSqI2jw7AAtnZ","status":1,"uploadSessionUrl":null}] | R12: https://epsongroup-my.sharepoint.com/personal/brian_ramdhani_epson_co_id/Documents/Apps/Microsoft%20Forms/TAKATSU%20ANALYZE%20REPORT/Question/Platen%20Fan%20NG,%20Platen%20Gap_Nazar%20Bagus%20H..jpg | S12: wa2Hg6noAEaJ4Mjn9p-_ssgAO1xP | X12: Gap on frame platen because not insert into dowel | AA12: repair platen become OK and check all Sub Assy Platen Unit | AB12: Nazar Bagus H.
B13: AR250108075823 | C13: 45665 | E13: Takatsu-4 Autocutter | F13: TKSAL-021 | G13: Platen Fan Adjustment NG | H13: Platen Fan Adjustment NG | I13: Low | J13: Operator | K13: PG | O13: Saat menu platen adjusmet | P13: During Platen Fan Adjustment, Value NG Minimum | Q13: [{"name":"Platen Fan NG 8 jan_Nazar Bagus H..jpg","link":"https://epsongroup-my.sharepoint.com/personal/brian_ramdhani_epson_co_id/Documents/Apps/Microsoft%20Forms/TAKATSU%20ANALYZE%20REPORT/Question/Platen%20Fan%20NG%208%20jan_Nazar%20Bagus%20H..jpg","id":"01D6UVHSOW6I54JX6ABBEIU5ZZRI4RPA7J","type":null,"size":54695,"referenceId":"01D6UVHSOX5DG5RX522VGYFCV365U3UBU3","driveId":"b!7qg8FsnQY0iiT36_x6Novv_3J9v4MtxPsytkCbb-ZPz3ScQFcxKeSqI2jw7AAtnZ","status":1,"uploadSessionUrl":null}] | R13: https://epsongroup-my.sharepoint.com/personal/brian_ramdhani_epson_co_id/Documents/Apps/Microsoft%20Forms/TAKATSU%20ANALYZE%20REPORT/Question/Platen%20Fan%20NG%208%20jan_Nazar%20Bagus%20H..jpg | S13: a1r_WbJ7O0G03uEu-42dvMgAGlnw | X13: terdapat value produk sebelumnya | AA13: reset semua value menggunakan kenpro menjadi OK | AB13: Nazar Bagus H.
B14: AR250109073004 | C14: 45666 | E14: Takatsu-8 Autocutter | F14: TKSAL-021 | G14: Platen Fan Adjustment NG | H14: Platen Fan Adjustment NG | I14: Low | J14: Operator | K14: PG | O14: Saat proses menu 4 platen fan adjustment | P14: During adjustment at PG Stage, found platen fan adjustment NG | Q14: [{"name":"Platen fan adjustment_Zainul Muttaqin.png","link":"https://epsongroup-my.sharepoint.com/personal/brian_ramdhani_epson_co_id/Documents/Apps/Microsoft%20Forms/TAKATSU%20ANALYZE%20REPORT/Question/Platen%20fan%20adjustment_Zainul%20Muttaqin.png","id":"01D6UVHSLFFFBVMFAQQFHKSSJ7XO4OA67I","type":null,"size":170890,"referenceId":"01D6UVHSOX5DG5RX522VGYFCV365U3UBU3","driveId":"b!7qg8FsnQY0iiT36_x6Novv_3J9v4MtxPsytkCbb-ZPz3ScQFcxKeSqI2jw7AAtnZ","status":1,"uploadSessionUrl":null}] | R14: https://epsongroup-my.sharepoint.com/personal/brian_ramdhani_epson_co_id/Documents/Apps/Microsoft%20Forms/TAKATSU%20ANALYZE%20REPORT/Question/Platen%20fan%20adjustment_Zainul%20Muttaqin.png | S14: l0NA-h58qEiE9cd2DOWy48gAMMwN | X14: Still analyze | AA14: Still analyze | AB14: Zainul Muttaqin
B15: AR250114125106 | C15: 45671 | E15: Takatsu-8 Autocutter | F15: TKSAL-021 | G15: Platen Fan Adjustment NG | H15: Platen Fan Adjustment NG | I15: Low | J15: Operator | K15: PG | O15: Still analize | P15: Platen Fan Adjustment Check NG | Q15: [{"name":"Platen Fan NG 8 jan_Nazar Bagus H. 2.jpg","link":"https://epsongroup-my.sharepoint.com/personal/brian_ramdhani_epson_co_id/Documents/Apps/Microsoft%20Forms/TAKATSU%20ANALYZE%20REPORT/Question/Platen%20Fan%20NG%208%20jan_Nazar%20Bagus%20H.%202.jpg","id":"01D6UVHSMPGIR3KENCNZC3PKDKYYBNPIZM","type":null,"size":54695,"referenceId":"01D6UVHSOX5DG5RX522VGYFCV365U3UBU3","driveId":"b!7qg8FsnQY0iiT36_x6Novv_3J9v4MtxPsytkCbb-ZPz3ScQFcxKeSqI2jw7AAtnZ","status":1,"uploadSessionUrl":null}] | R15: https://epsongroup-my.sharepoint.com/personal/brian_ramdhani_epson_co_id/Documents/Apps/Microsoft%20Forms/TAKATSU%20ANALYZE%20REPORT/Question/Platen%20Fan%20NG%208%20jan_Nazar%20Bagus%20H.%202.jpg | S15: uyxxFDEdqU2y0YzlMXER08gABOQ3 | X15: Drum Shutter Position NG | AA15: reset Shutter Drum Position Become OK | AB15: Nazar Bagus H.
